<?xml version="1.0" encoding="utf-8"?>
<!-- =================================================================================== -->
<!-- |    This document was autogenerated by xacro from OneLeg_light.urdf.xacro        | -->
<!-- |    EDITING THIS FILE BY HAND IS NOT RECOMMENDED                                 | -->
<!-- =================================================================================== -->
<robot name="oneleg">
  <link name="world"/>
  <joint name="body_base" type="floating">
    <origin rpy="0 0 0" xyz="0 0 0"/>
    <parent link="world"/>
    <child link="foot"/>
  </joint>


  <link name="foot">
    <inertial>
      <origin rpy="0 0 0" xyz="0 0 0.025"/>
      <mass value="0.55"/>
      <inertia ixx="0.001" ixy="0" ixz="0" iyy="0.001" iyz="0" izz="0.001"/>
    </inertial>
    <visual>
        <origin xyz="0 0 0.01" rpy="0 0 0"/>
        <geometry>
	        <box size="0.15 0.20 0.02"/>
        </geometry>	
    </visual>
    <visual>
        <origin xyz="0 0 0.0375" rpy="0 0 0"/>
        <geometry>
            <cylinder length="0.075" radius="0.025"/>
        </geometry> 
    </visual>
    <visual>
        <origin xyz="0 0 0.075" rpy="0 1.571 0"/>
        <geometry>
            <cylinder length="0.06" radius="0.025"/>
        </geometry> 
    </visual>
    <collision>
        <origin xyz="0 0 0.01" rpy="0 0 0"/>
        <geometry>
	        <box size="0.15 0.20 0.02"/>
        </geometry>	
    </collision>
    <collision>
        <origin xyz="0 0 0.04" rpy="0 0 0"/>
        <geometry>
            <cylinder length="0.06" radius="0.025"/>
        </geometry> 
    </collision>
    <collision>
        <origin xyz="0 0 0.075" rpy="0 1.571 0"/>
        <geometry>
            <cylinder length="0.06" radius="0.025"/>
        </geometry> 
    </collision>
  </link>
  

    <joint name="ankle" type="revolute">
        <origin xyz="0 0 0.075" rpy="0 0 0"/> 
        <parent link="foot"/>
        <child link="calf"/>
        <limit effort="300" velocity="100" lower="-3.14" upper="3.14" />
        <axis xyz="1 0 0"/>
        <dynamics damping="0.4" friction="0.2"/>
    </joint> 


     
  <link name="calf">
    <inertial>
      <origin rpy="0 0 0" xyz="0 0 0.09"/>
      <mass value="1"/>
      <inertia ixx="0.001" ixy="0" ixz="0" iyy="0.001" iyz="0" izz="0.001"/>
    </inertial>
    <visual>
        <origin xyz="0 0 0.09" rpy="0 0 0"/>
        <geometry>
            <cylinder length="0.18" radius="0.025"/>
        </geometry> 
    </visual>
    <visual>
        <origin xyz="0 0 0.18" rpy="0 1.571 0"/>
        <geometry>
            <cylinder length="0.06" radius="0.025"/>
        </geometry> 
    </visual>
    <collision>
        <origin xyz="0 0 0.09" rpy="0 0 0"/>
        <geometry>
            <cylinder length="0.18" radius="0.025"/>
        </geometry> 
    </collision>
    <collision>
        <origin xyz="0 0 0.18" rpy="0 1.571 0"/>
        <geometry>
            <cylinder length="0.06" radius="0.025"/>
        </geometry> 
    </collision>
  </link>
 

    <joint name="knee" type="revolute">
        <origin xyz="0 0 0.18" rpy="0 0 0"/> 
        <parent link="calf"/>
        <child link="thigh"/>
        <limit effort="300" velocity="100" lower="-3.14" upper="3.14" />
        <axis xyz="1 0 0"/>
        <dynamics damping="0.4" friction="0.2"/>
    </joint> 

  <link name="thigh">
    <inertial>
      <origin rpy="0 0 0" xyz="0 0 0.06"/>
      <mass value="0.7"/>
      <inertia ixx="0.001" ixy="0" ixz="0" iyy="0.001" iyz="0" izz="0.001"/>
    </inertial>
    <visual>
        <origin xyz="0 0 0.06" rpy="0 0 0"/>
        <geometry>
            <cylinder length="0.12" radius="0.025"/>
        </geometry> 
    </visual>
    <visual>
        <origin xyz="0 0 0.12" rpy="0 1.571 0"/>
        <geometry>
            <cylinder length="0.06" radius="0.025"/>
        </geometry> 
    </visual>
    <collision>
        <origin xyz="0 0 0.06" rpy="0 0 0"/>
        <geometry>
            <cylinder length="0.12" radius="0.025"/>
        </geometry> 
    </collision>
    <collision>
        <origin xyz="0 0 0.12" rpy="0 1.571 0"/>
        <geometry>
            <cylinder length="0.06" radius="0.025"/>
        </geometry> 
    </collision>
  </link>

    <joint name="hip" type="revolute">
        <origin xyz="0 0 0.12" rpy="0 0 0"/> 
        <parent link="thigh"/>
        <child link="hiplink"/>
        <limit effort="300" velocity="100" lower="-3.14" upper="3.14" />
        <axis xyz="1 0 0"/>
        <dynamics damping="0.4" friction="0.2"/>
    </joint> 

  <link name="hiplink">
    <inertial>
      <origin rpy="0 0 0" xyz="0 0 0.04"/>
      <mass value="0.45"/>
      <inertia ixx="0.001" ixy="0" ixz="0" iyy="0.001" iyz="0" izz="0.001"/>
    </inertial>
    <visual>
        <origin xyz="0 0 0.04" rpy="0 0 0"/>
        <geometry>
            <cylinder length="0.08" radius="0.025"/>
        </geometry> 
    </visual>
    <collision>
        <origin xyz="0 0 0.04" rpy="0 0 0"/>
        <geometry>
            <cylinder length="0.08" radius="0.025"/>
        </geometry> 
    </collision>
  </link>

  <joint name="bodyjoint" type="fixed">
    <origin rpy="0 0 0" xyz="0 0 0.08"/>
    <parent link="hiplink"/>
    <child link="body"/>
  </joint>

  <link name="body">
    <inertial>
      <origin rpy="0 0 0" xyz="0 0 0.07"/>
      <mass value="0.5"/>
      <inertia ixx="0.001" ixy="0" ixz="0" iyy="0.001" iyz="0" izz="0.001"/>
    </inertial>
    <visual>
      <origin rpy="0 0 1.571" xyz="0 0 0"/>
      <geometry>
        <box size="0.066 0.25 0.02"/>
      </geometry>
    </visual>
    <visual>
      <origin rpy="0 0 1.571" xyz="0 0 0.06"/>
      <geometry>
        <box size="0.12 0.18 0.11"/>
      </geometry>
    </visual>
    <collision>
      <origin rpy="0 0 1.571" xyz="0 0 0"/>
      <geometry>
        <box size="0.066 0.25 0.02"/>
      </geometry>
    </collision>
    <collision>
      <origin rpy="0 0 1.571" xyz="0 0 0.06"/>
      <geometry>
        <box size="0.12 0.18 0.11"/>
      </geometry>
    </collision>
  </link>

    # GAZEBO PLUGIN
    
  <gazebo>
    <plugin filename="libsea_plugin.so" name="leg_sea_1">
      <joint>ankle</joint>
      <namespace>oneleg</namespace>
      <stiffness>20</stiffness>
      <pub_eltau>false</pub_eltau>
      <pub_state>true</pub_state>
      <sub_ext_tau>false</sub_ext_tau>
    </plugin>
  </gazebo>
  <gazebo>
    <plugin filename="libsea_plugin.so" name="leg_sea_2">
      <joint>knee</joint>
      <namespace>oneleg</namespace>
      <stiffness>20</stiffness>
      <pub_eltau>false</pub_eltau>
      <pub_state>true</pub_state>
      <sub_ext_tau>false</sub_ext_tau>
    </plugin>
  </gazebo>
  <gazebo>
    <plugin filename="libsea_plugin.so" name="leg_sea_3">
      <joint>hip</joint>
      <namespace>oneleg</namespace>
      <stiffness>20</stiffness>
      <pub_eltau>false</pub_eltau>
      <pub_state>true</pub_state>
      <sub_ext_tau>false</sub_ext_tau>
    </plugin>
  </gazebo>
  <gazebo>
    <self_collide>1</self_collide>
  </gazebo>


  <gazebo reference="body">
    <material>Gazebo/Grey</material>
  </gazebo>

  <gazebo reference="hiplink">
    <material>Gazebo/Red</material>
  </gazebo>

  <gazebo reference="thigh">
    <material>Gazebo/Green</material>
  </gazebo>

  <gazebo reference="calf">
    <material>Gazebo/Blue</material>
  </gazebo>

  <gazebo reference="foot">
    <mu1>10</mu1>
    <mu2>10</mu2>
    <kd>20</kd>
    <material>Gazebo/Orange</material>
  </gazebo>

</robot>

